Workbook
Name \X: '[1]URA-C1'!#REF!
Name \z: '[2]URA-C1'!#REF!
Name ____CNF1: [3]BULD.3!#REF!
Name ____CNF12: [3]BULD.3!#REF!
Name ____CNH1: #REF!
Name ____frw4: [3]BULD.3!#REF!
Name ____frw42: [3]BULD.3!#REF!
Name ____hbs2: [3]BULD.3!#REF!
Name ____hbs22: [3]BULD.3!#REF!
Name ____hbs3: [3]BULD.3!$A$42
Name ____hbs32: [3]BULD.3!$B$42
Name ____hcs300: [3]BULD.3!#REF!
Name ____hcs3001: [3]BULD.3!#REF!
Name ____HCS3002: [3]BULD.3!#REF!
Name ____pcf1: [3]BULD.3!#REF!
Name ____pcf12: [3]BULD.3!#REF!
Name ____pcf2: [3]BULD.3!#REF!
Name ____pcf22: [3]BULD.3!#REF!
Name ____pcf3: [3]BULD.3!$A$11
Name ____pcf32: [3]BULD.3!$B$11
Name ____pcf4: [3]BULD.3!#REF!
Name ____pcf42: [3]BULD.3!#REF!
Name ____pcf5: [3]BULD.3!#REF!
Name ____pcf52: [3]BULD.3!#REF!
Name ____pcg1: [3]BULD.3!#REF!
Name ____pcg12: [3]BULD.3!#REF!
Name ____pcg2: [3]BULD.3!#REF!
Name ____pcg22: [3]BULD.3!#REF!
Name ____pcg3: [3]BULD.3!$A$13
Name ____pcg32: [3]BULD.3!$B$13
Name ____pcg4: [3]BULD.3!#REF!
Name ____pcg42: [3]BULD.3!#REF!
Name ____pcg5: [3]BULD.3!#REF!
Name ____pcg52: [3]BULD.3!#REF!
Name ____rcc2: [3]BULD.3!#REF!
Name ____rcc22: [3]BULD.3!#REF!
Name ____rcc3: [3]BULD.3!$A$34
Name ____rcc32: [3]BULD.3!$B$34
Name ____rcc52: [3]BULD.3!#REF!
Name ____rcf1: [3]BULD.3!#REF!
Name ____rcf12: [3]BULD.3!#REF!
Name ____rcf2: [3]BULD.3!#REF!
Name ____rcf22: [3]BULD.3!#REF!
Name ____rcf3: [3]BULD.3!$A$19
Name ____rcf32: [3]BULD.3!$B$19
Name ____rcf4: [3]BULD.3!#REF!
Name ____rcf42: [3]BULD.3!#REF!
Name ____RCF5: [3]BULD.3!#REF!
Name ____RCF52: [3]BULD.3!#REF!
Name ____rw3: [3]BULD.3!$B$27
Name ____rw32: [3]BULD.3!$A$27
Name ____rw4: [3]BULD.3!#REF!
Name ____rw42: [3]BULD.3!#REF!
Name ____rwf3: [3]BULD.3!$A$31
Name ____rwf32: [3]BULD.3!$B$31
Name ____src1: [3]BULD.3!#REF!
Name ____ssf2: [3]BULD.3!#REF!
Name ____ssf22: [3]BULD.3!#REF!
Name ____ssf3: [3]BULD.3!$A$38
Name ____ssf32: [3]BULD.3!$B$38

Sheet Summary
A2: SGH Makkah OPD Expansion Abstract
A3: S. No. | B3: DESCRIPTION | C3: Amount (SAR)
A5: 1 | B5: GENERAL REQUIREMENTS
A7: 2 | B7: CIVIL & ARCHITECTURAL WORKS
A9: 3 | B9: MECHANICAL WORKS
A11: 4 | B11: ELECTRICAL & LC WORKS | C11: =Electrical!F88+'Low Current'!F115 -> 2355553
B13: Low Current-missing | C13: ='Low Current-missing'!F124 -> 1036091
A15: 5 | B15: MEDICAL GASES WORKS
A17: 6 | B17: DESIGN WORKS
B19: GRAND TOTAL | C19: =SUM(C5:C18) -> 3391644 | E19: =C11/1360 -> 1732.0243

Sheet Electrical
A2: Electrical Works | J2: 1
A3: Item No. | B3: Description | C3: Unit | D3: Qty | E3: Unit Rate | F3: Amount | G3: العام | H3: Best | I3: Supplier | J3: O&P% | K3: Dry (O) | L3: OUTLET (P)مخرج الكهربا | M3: Supply (Q) | N3: Wastage (R) | O3: Install (S) | P3: Access (T) | Q3: ملاحظات | R3: الموردون
A4: 16 | B4: ELECTRICAL
B6: POWER AND LIGHTING | M6: لوحات التوزيع الكهربائية
A7: 16.1 | B7: Main installation supply, installation, testing and commissioning of main electric and sub main distribution panels including the busbar, main breaker, branch breakers(M.C.CBS) metering equipment and all other accessories. The board shall be furnished with current transformers for measurments and protection, and microprocessor based network analyzer to meter and analyze at least 3PH .current , voltage , KWH , KWHR. power factor, frequency ..etc. All panel boards should be monitored and lighting panel boards to be monitored and controlled by BMS. As specified and/or detailed on the drawings and as per method of measurement and specifications . | Q7: اللوحات مطلوب بها بتشمل (Busbar, Main Breaker, Branch Breakers, CTs, Network Analyzer, BMS Integration).
A8: 16.1-1 | B8: DB-N4A-1F | C8: No. | D8: 1 | E8: =ROUNDUP(H8*$J$2,0) -> 14000 | F8: =D8*E8 -> 14000 | G8: لوحات كهربائية | H8: =K8 -> 14000 | I8: Schneider Electric | K8: =L8+M8+N8+O8+P8 -> 14000 | L8: 0 | M8: 11700 | N8: 200 | O8: 1600 | P8: 500 | R8: Schneider
A9: 16.1-2 | B9: DB-N4B-1F | C9: No. | D9: 1 | E9: =ROUNDUP(H9*$J$2,0) -> 12700 | F9: =D9*E9 -> 12700 | G9: لوحات كهربائية | H9: =K9 -> 12700 | I9: Schneider Electric | K9: =L9+M9+N9+O9+P9 -> 12700 | L9: 0 | M9: 10400 | N9: 200 | O9: 1600 | P9: 500 | R9: Schneider
A10: 16.1-3 | B10: DB-LN4-1F | C10: No. | D10: 1 | E10: =ROUNDUP(H10*$J$2,0) -> 11400 | F10: =D10*E10 -> 11400 | G10: لوحات كهربائية | H10: =K10 -> 11400 | I10: Schneider Electric | K10: =L10+M10+N10+O10+P10 -> 11400 | L10: 0 | M10: 9100 | N10: 200 | O10: 1600 | P10: 500 | R10: Schneider
A11: 16.1-4 | B11: DB-LE4-1F | C11: No. | D11: 1 | E11: =ROUNDUP(H11*$J$2,0) -> 10100 | F11: =D11*E11 -> 10100 | G11: لوحات كهربائية | H11: =K11 -> 10100 | I11: Schneider Electric | K11: =L11+M11+N11+O11+P11 -> 10100 | L11: 0 | M11: 7800 | N11: 200 | O11: 1600 | P11: 500 | R11: Schneider
A12: 16.1-5 | B12: DB-E4-1F | C12: No. | D12: 1 | E12: =ROUNDUP(H12*$J$2,0) -> 9450 | F12: =D12*E12 -> 9450 | G12: لوحات كهربائية | H12: =K12 -> 9450 | I12: Schneider Electric | K12: =L12+M12+N12+O12+P12 -> 9450 | L12: 0 | M12: 7150 | N12: 200 | O12: 1600 | P12: 500 | R12: Schneider
A13: 16.1-6 | B13: DB-U3-1F | C13: No. | D13: 1 | E13: =ROUNDUP(H13*$J$2,0) -> 8475 | F13: =D13*E13 -> 8475 | G13: لوحات كهربائية | H13: =K13 -> 8475 | I13: Schneider Electric | K13: =L13+M13+N13+O13+P13 -> 8475 | L13: 0 | M13: 6175 | N13: 200 | O13: 1600 | P13: 500 | R13: Schneider
A14: 16.1-7 | B14: DB-LU2-1F | C14: No. | D14: 1 | E14: =ROUNDUP(H14*$J$2,0) -> 7825 | F14: =D14*E14 -> 7825 | G14: لوحات كهربائية | H14: =K14 -> 7825 | I14: Schneider Electric | K14: =L14+M14+N14+O14+P14 -> 7825 | L14: 0 | M14: 5525 | N14: 200 | O14: 1600 | P14: 500 | R14: Schneider
A15: 16.1-8 | B15: LCP4-1F ( KNX ) | C15: No. | D15: 1 | E15: =ROUNDUP(H15*$J$2,0) -> 36400 | F15: =D15*E15 -> 36400 | G15: لوحات كهربائية | H15: =K15 -> 36400 | I15: Schneider Electric | K15: =L15+M15+N15+O15+P15 -> 36400 | L15: 0 | M15: 30000 | N15: 400 | O15: 5000 | P15: 1000 | R15: Schneider
B18: POWER & CONTROL CABLES : | M18: الكابلات
A20: 16.8 | B20: supply & install multi-core non-armored and armored cables, LS0H 0.6/1.0kv. copper/XLPE/PVC. feeding mechanical& or electrical loads runs in cable trays, above false ceiling or in the shaft or in the condiuts, with all fixing and connecting accessories (the glands and lugs copper made), as detailed in technical specifications and shown on drawing and as per method of measurement and specifications . | Q20: (فخ أسطوري): في مشروع بحجم 1126 متر مربع، فيه 327 نقطة قوى و 284 نقطة إنارة (كما بالبند 16.9 و 16.11)، مفيش طريق في الدنيا إن الكابلات دي تطلع أطوالها "مئوية" زي كده بالظبط!
A21: 16.8-1 | B21: (4C-10 MM2 CU/XLPE/PVC) | C21: LM | D21: 1000 | E21: =ROUNDUP(H21*$J$2,0) -> 42 | F21: =D21*E21 -> 42000 | G21: كابلات تغذية | H21: =K21 -> 41.65 | I21: Riyadh Cables | K21: =L21+M21+N21 -> 41.65 | L21: 0 | M21: 40 | N21: 1.65 | O21: 13.75 | P21: 2 | R21: Riyadh Cables
A22: 16.8-2 | B22: (4C-35 MM2 CU/XLPE/PVC) | C22: LM | D22: 1000 | E22: =ROUNDUP(H22*$J$2,0) -> 127 | F22: =D22*E22 -> 127000 | G22: كابلات تغذية | H22: =K22 -> 127 | I22: Riyadh Cables | K22: =L22+M22+N22 -> 127 | L22: 0 | M22: 125 | N22: 2 | O22: 30 | P22: 2 | R22: Riyadh Cables
A23: 16.8-3 | B23: (4C-50 MM2 CU/XLPE/PVC) | C23: LM | D23: 400 | E23: =ROUNDUP(H23*$J$2,0) -> 200 | F23: =D23*E23 -> 80000 | G23: كابلات تغذية | H23: =K23 -> 200 | I23: Riyadh Cables | K23: =L23+M23+N23 -> 200 | L23: 0 | M23: 198 | N23: 2 | O23: 40 | P23: 2 | R23: Riyadh Cables
A24: 16.8-4 | B24: (1C-10MM2 Y/G) | C24: LM | D24: 1000 | E24: =ROUNDUP(H24*$J$2,0) -> 16 | F24: =D24*E24 -> 16000 | G24: كابلات تغذية | H24: =K24 -> 15.54 | I24: Riyadh Cables | K24: =L24+M24+N24 -> 15.54 | L24: 0 | M24: 15 | N24: 0.54 | O24: 4 | P24: 1 | R24: Riyadh Cables
A25: 16.8-5 | B25: (1C-16MM2 Y/G) | C25: LM | D25: 1000 | E25: =ROUNDUP(H25*$J$2,0) -> 20 | F25: =D25*E25 -> 20000 | G25: كابلات تغذية | H25: =K25 -> 19.84 | I25: Riyadh Cables | K25: =L25+M25+N25 -> 19.84 | L25: 0 | M25: 19 | N25: 0.84 | O25: 5 | P25: 1 | R25: Riyadh Cables
A26: 16.8-6 | B26: (1C-25MM2 Y/G) | C26: LM | D26: 400 | E26: =ROUNDUP(H26*$J$2,0) -> 30 | F26: =D26*E26 -> 12000 | G26: كابلات تغذية | H26: =K26 -> 29.26 | I26: Riyadh Cables | K26: =L26+M26+N26 -> 29.26 | L26: 0 | M26: 28 | N26: 1.26 | O26: 7 | P26: 1 | R26: Riyadh Cables
A27: 16.8-7 | B27: Cable Lugs, Gland & Terminations | C27: LS | D27: 1 | E27: =ROUNDUP(H27*$J$2,0) -> 78750 | F27: =D27*E27 -> 78750 | G27: كابلات تغذية | H27: =K27 -> 78750 | I27: Burndy | K27: =L27+M27+N27+O27+P27 -> 78750 | L27: 0 | O27: =SUMPRODUCT($D$21:$D$26,$O$21:$O$26) -> 71550 | P27: =SUMPRODUCT($D$21:$D$26,$P$21:$P$26) -> 7200 | R27: Riyadh Cables
B29: Power Sockets and Switches | M29: مخارج القوى والأفياش
A30: 16.9 | B30: supply , install, testing and commissioning of socket outlets, switches, exhaust fan points and other power points , included all swiches with indication lamps, push buttons , cables ,wiring, conduits , trunks , boxes and all needed accessories to complete the work as per bill of quantities , drawings , specifications and engineers instructions and approval and as per method of measurement and specifications .wire size 4MM² .
A31: 16.9-1 | B31: Power Points (Conduing & Wiring with Accessories) | C31: No. | D31: 327 | E31: =ROUNDUP(H31*$J$2,0) -> 270 | F31: =D31*E31 -> 88290 | G31: مخارج قوى وأفياش | H31: =K31 -> 269.1 | I31: Legrand | K31: =(Table1[[#This Row],[OUTLET (P)مخرج الكهربا ]]/6)+Table1[[#This Row],[Wastage (R)]]+Table1[[#This Row],[Access (T)]] -> 269.1 | L31: =L32+L33+L34+L35+L36+L37 -> 1554.6 | N31: 5 | P31: 5 | R31: Legrand
A32: 16.9-2 | B32: 1 G 1W Switch | C32: No. | D32: 100 | E32: =ROUNDUP(H32*$J$2,0) -> 56 | F32: =D32*E32 -> 5600 | G32: مفاتيح إنارة | H32: =K32 -> 56 | I32: Legrand | K32: =M32+N32+O32+P32 -> 56 | L32: ='بريك داون كهرباء'!Q24 -> 170 | M32: 40 | N32: 3 | O32: 10 | P32: 3 | R32: Legrand
A33: 16.9-3 | B33: 2 G 1W Switch | C33: No. | D33: 20 | E33: =ROUNDUP(H33*$J$2,0) -> 83 | F33: =D33*E33 -> 1660 | G33: مفاتيح إنارة | H33: =K33 -> 83 | I33: Legrand | K33: =M33+N33+O33+P33 -> 83 | L33: ='بريك داون كهرباء'!Q25 -> 251 | M33: 65 | N33: 3 | O33: 10 | P33: 5 | R33: Legrand
A34: 16.9-4 | B34: Single socket Berker 1G | C34: No. | D34: 130 | E34: =ROUNDUP(H34*$J$2,0) -> 96 | F34: =D34*E34 -> 12480 | G34: مخارج قوى وأفياش | H34: =K34 -> 96 | I34: Berker | K34: =M34+N34+O34+P34 -> 96 | L34: ='بريك داون كهرباء'!Q26 -> 170 | M34: 80 | N34: 3 | O34: 10 | P34: 3 | R34: Legrand
A35: 16.9-5 | B35: Duplex socket Berker 1G for PVC trunking | C35: No. | D35: 70 | E35: =ROUNDUP(H35*$J$2,0) -> 148 | F35: =D35*E35 -> 10360 | G35: مخارج قوى وأفياش | H35: =K35 -> 148 | I35: Berker | K35: =M35+N35+O35+P35 -> 148 | L35: ='بريك داون كهرباء'!Q27 -> 170 | M35: 130 | N35: 3 | O35: 10 | P35: 5 | R35: Legrand
A36: 16.9-6 | B36: Industrial low voltage socket 5 pin 30A | C36: No. | D36: 5 | E36: =ROUNDUP(H36*$J$2,0) -> 371 | F36: =D36*E36 -> 1855 | G36: مخارج قوى وأفياش | H36: =K36 -> 370.6 | I36: Legrand | K36: =M36+N36+O36+P36 -> 370.6 | L36: ='بريك داون كهرباء'!Q28 -> 514 | M36: 250 | N36: 20.6 | O36: 80 | P36: 20 | R36: Legrand
A37: 16.9-7 | B37: Recessed type floor box with 2 compartments and push opening option | C37: No. | D37: 2 | E37: =ROUNDUP(H37*$J$2,0) -> 866 | F37: =D37*E37 -> 1732 | G37: مخارج قوى وأفياش | H37: =K37 -> 865.5 | I37: Legrand | K37: =M37+N37+O37+P37 -> 865.5 | L37: ='بريك داون كهرباء'!Q29 -> 279.6 | M37: 797.5 | N37: 10 | O37: 50 | P37: 8 | Q37: دي في مستشفيات بتكون مكلفة جداً لأنها Anti-bacterial ومقاومة للماء، وسعرها بيختلف خالص عن الـ Floor Box العادي. | R37: Legrand
B39: Isolators :
A40: 16.1 | B40: supply, install and connect isolator outlet included all cables, wires, conduits, trunks, boxes and all needed accessories to complete the work as per bill of quantities , drawings , specifications and engineers instructions and approval and as per method of measurement and specifications .
A41: 16.10-1 | B41: 32 A ISOLATOR TPN | C41: No. | D41: 20 | E41: =ROUNDUP(H41*$J$2,0) -> 879 | F41: =D41*E41 -> 17580 | G41: مخارج قوى وأفياش | H41: =K41 -> 879 | I41: Schneider Electric | K41: =L41+M41+N41+O41+P41 -> 879 | L41: ='بريك داون كهرباء'!Q30 -> 534 | M41: 280 | N41: 10 | O41: 50 | P41: 5 | R41: mk
B43: Lighting system : | M43: نظام الإنارة
A44: 16.11 | B44: supply, install &connect, complete indoor and outdoor lighting points including , conduits boxes , wires , impulse relay swiches or swich panels and all other accessories from the appropriate bistribution board to the point as specified and/or detailed on the drawings and as per method of measurement and specifications . with wire size 2.5MM² .
A45: 16.11-1 | B45: Lighting Points (Conduing & Wiring with Accessories) | C45: No. | D45: 284 | E45: =ROUNDUP(H45*$J$2,0) -> 166 | F45: =D45*E45 -> 47144 | G45: إنارة داخلية | H45: =K45 -> 165.31818 | K45: =(Table1[[#This Row],[OUTLET (P)مخرج الكهربا ]])+Table1[[#This Row],[Wastage (R)]]+Table1[[#This Row],[Access (T)]] -> 165.31818 | L45: =(L46+L47+L48+L49+L50+L51+L52+L53+L54+L55+L56+L57)/11 -> 155.31818 | N45: 5 | P45: 5
A46: 16.11-2 | B46: Type - L1 , Square down light 23w , IP44 , 230V , 60HZ | C46: No. | D46: 80 | E46: =ROUNDUP(H46*$J$2,0) -> 173 | F46: =D46*E46 -> 13840 | G46: إنارة داخلية | H46: =K46 -> 173 | I46: siera | K46: =M46+N46+O46+P46 -> 173 | L46: ='بريك داون كهرباء'!Q33 -> 153.5 | M46: 125 | N46: 5 | O46: 40 | P46: 3
A47: 16.11-3 | B47: Type - L2 , Square Panel down light 16w , 230v , IP44 , 5000K | C47: No. | D47: 20 | E47: =ROUNDUP(H47*$J$2,0) -> 197 | F47: =D47*E47 -> 3940 | G47: إنارة داخلية | H47: =K47 -> 196.55 | I47: siera | K47: =M47+N47+O47+P47 -> 196.55 | L47: ='بريك داون كهرباء'!Q34 -> 153.5 | M47: 140 | N47: 13.55 | O47: 40 | P47: 3
A48: 16.11-4 | B48: Type - L3 , Square spot light 5w , 230V , IP23 , 3000K | C48: No. | D48: 20 | E48: =ROUNDUP(H48*$J$2,0) -> 156 | F48: =D48*E48 -> 3120 | G48: إنارة داخلية | H48: =K48 -> 155.75 | I48: siera | K48: =M48+N48+O48+P48 -> 155.75 | L48: ='بريك داون كهرباء'!Q35 -> 153.5 | M48: 82 | N48: 10.75 | O48: 60 | P48: 3
...

Sheet Low Current
A2: Low Current | J2: 1
A3: Item No. | B3: Description | C3: Unit | D3: Qty | E3: Unit Price (SR) | F3: Amount ( SR ) | G3: العام | H3: Best | I3: Supplier | J3: O&P% | K3: Dry (O) | L3: OUTLET (P) | M3: Supply (Q) | N3: Wastage (R) | O3: Install (S) | P3: Access (T) | Q3: ملاحظات | R3: الموردون
A4: 16.17 | B4: PUBLIC ADDRESS SYSTEM & EVACUATION SYSTEM : | G4: نظام الإذاعة PA والإخلاء
B5: Supply, install, testing and commissioning for public address and evacuation system consisting of Main Rack and Zone controller, Racks, digital audio matrix / main controller, amplifier units, Loudspeakers, call stations, volume controls and operation devices including batteries and chargers (for a minimum continuous evacuation period as per the Life Safety designation but not less than 2 hours), fire rated fiber and audio cables and wires, conduits, supports, and wire connection , interfacing works with other systems including Fire Alarm and BMS, Prayer Audio System and Master Clock as shown on drawings and described in specifications SECTION 16770 and as per Civil Defense requirements. | C5: Each | D5: 1 | E5: =ROUNDUP(H5*$J$2,0) -> 70767 | F5: =D5*E5 -> 70767 | G5: نظام PA - إذاعة | H5: =K5 -> 70767 | I5: Bosch | K5: =L5+M5+N5+O5+P5 -> 70767 | L5: 317 | M5: =18500+8750+14200+6400+3700+8000+5000 -> 64550 | N5: 400 | O5: 5000 | P5: 500 | Q5: (Zone Controller+Amplifier Units+Digital Audio Matrix / Main Controller+Call Stations+Main Rack for Public Address & Evacuation Systemفي الوصف( إنه لازم ي interfaced مع (Fire Alarm, BMS, Prayer Audio, Master Clock). الـ Integration بتاع المستشفيات بيحتاج برمجة مكلفة من الـ Vendor. سعر الـ LS بتاعك لازم يشمل الـ Hardware والـ Software والـ Integration والـ Programming. | R5: FINOSEL-Bosch-TOA-Exide / Trojan-MESK
B6: Supply install and test and commission public adress & evacutaion system include loud speaker pionts , verification of the desin box , conduit , 2x2.5mm2 cables from each piont to voice rack and all needed accessories tto complte the work as per Boq and drawings , specifications , civill defence department requirment
B7: notes : all materials shall be fire rated
B8: All speakers 5W-8W
A9: 16.17.1 | B9: L-VCP06A/EN 6W Ceiling Loudspeaker ABS back box EN54 | C9: Each | D9: 32 | E9: =ROUNDUP(H9*$J$2,0) -> 671 | F9: =D9*E9 -> 21472 | G9: نظام PA - إذاعة | H9: =K9 -> 670.8 | I9: Bosch | K9: =L9+M9+N9+O9+P9 -> 670.8 | L9: ='بريك داون تيار خفيف'!Q4 -> 142.8 | M9: 510 | N9: 8 | P9: 10 | Q9: Ceiling-mounted speaker with EN54 compliance | R9: Bosch / TOA / Harman
A10: 16.17.2 | B10: L-VWM06A/ENVA LS - 6W Metal Wall Mount | C10: Each | D10: 4 | E10: =ROUNDUP(H10*$J$2,0) -> 778 | F10: =D10*E10 -> 3112 | G10: نظام PA - إذاعة | H10: =K10 -> 777.8 | I10: Bosch | K10: =L10+M10+N10+O10+P10 -> 777.8 | L10: ='بريك داون تيار خفيف'!Q5 -> 142.8 | M10: 620 | N10: 5 | P10: 10 | Q10: Wall-mounted metal loudspeaker | R10: Bosch / TOA
A11: 16.17.3 | B11: [L-PHP30A] HORN LOUDSPEAKER 630/15W WITH ABS | C11: Each | D11: 8 | E11: =ROUNDUP(H11*$J$2,0) -> 558 | F11: =D11*E11 -> 4464 | G11: نظام PA - إذاعة | H11: =K11 -> 557.8 | I11: Bosch | K11: =L11+M11+N11+O11+P11 -> 557.8 | L11: ='بريك داون تيار خفيف'!Q6 -> 142.8 | M11: 400 | N11: 5 | P11: 10 | Q11: Horn loudspeaker for outdoor use | R11: Bosch / TOA / Harman
A12: 16.17.4 | B12: Volume Control Switch 60W [60VC-HN [60VCHN 4 With Protection Circuit, White | C12: Each | D12: 6 | E12: =ROUNDUP(H12*$J$2,0) -> 908 | F12: =D12*E12 -> 5448 | G12: نظام PA - إذاعة | H12: =K12 -> 907.8 | I12: Bosch | K12: =L12+M12+N12+O12+P12 -> 907.8 | L12: ='بريك داون تيار خفيف'!Q7 -> 142.8 | M12: 750 | N12: 5 | P12: 10 | Q12: Wall-mounted volume control with protection | R12: Bosch / TOA
A13: 16.17.5 | B13: wireless microphone | C13: Each | D13: 1 | E13: =ROUNDUP(H13*$J$2,0) -> 4210 | F13: =D13*E13 -> 4210 | G13: نظام PA - إذاعة | H13: =K13 -> 4210 | I13: Bosch | K13: =L13+M13+N13+O13+P13 -> 4210 | L13: ='بريك داون تيار خفيف'!Q8 -> 0 | M13: 4200 | N13: 5 | P13: 5 | Q13: Wireless microphone for audio system | R13: Bosch / Sennheiser / Shure
A14: 16.17.6 | B14: Testing and Commissioning | C14: Each | D14: 1 | E14: =ROUNDUP(H14*$J$2,0) -> 5000 | F14: =D14*E14 -> 5000 | G14: نظام PA - إذاعة | H14: =K14 -> 5000 | K14: 5000 | Q14: System testing and commissioning | R14: شركات متخصصة
A15: 16.17.7 | B15: Installation | C15: Lot | D15: 1 | E15: =ROUNDUP(H15*$J$2,0) -> 15000 | F15: =D15*E15 -> 15000 | G15: نظام PA - إذاعة | H15: =K15 -> 15000 | K15: 15000 | Q15: Complete installation service | R15: شركات متخصصة
H17: =K17 -> 0 | K17: =L17+M17+N17+O17+P17 -> 0
A18: 16.18 | B18: MASTER CLOCK SYSTEM : | G18: MASTER CLOCK SYSTEM
A19: 16.18.1 | B19: SAPLING SINGLE SIDE DIGITAL IP CLOCK, 3100 MODEL, 4.0", 4 DIGITS, POE, RED DISPLAY, SURFACE WALL MOUNT | C19: Each | D19: 4 | E19: =ROUNDUP(H19*$J$2,0) -> 1530 | F19: =D19*E19 -> 6120 | G19: شبكة MATV | H19: =K19 -> 1530 | I19: Sapling | K19: =L19+M19+N19+O19+P19 -> 1530 | M19: 1500 | N19: 10 | P19: 20 | Q19: ساعة رقمية IP بواجهة حائط، عرض أحمر
A20: 16.18.2 | B20: DOUBLE MOUNT HOUSING FOR ABOVE | C20: Each | D20: 2 | E20: =ROUNDUP(H20*$J$2,0) -> 420 | F20: =D20*E20 -> 840 | G20: شبكة MATV | H20: =K20 -> 420 | I20: Sapling | K20: =L20+M20+N20+O20+P20 -> 420 | M20: 390 | N20: 10 | P20: 20 | Q20: قاعدة تثبيت مزدوجة للساعة
A21: 16.18.3 | B21: PROGRAMMING, TESTING & COMMISSIONING | C21: Each | D21: 1 | E21: =ROUNDUP(H21*$J$2,0) -> 4510 | F21: =D21*E21 -> 4510 | G21: شبكة MATV | H21: =K21 -> 4510 | I21: Sapling | K21: =L21+M21+N21+O21+P21 -> 4510 | M21: 4500 | N21: 10 | Q21: برمجة، اختبار وتشغيل النظام
A22: 16.18.4 | B22: SMALL ORDER DOCUMENTATION & HANDLING CHARGES (APPLICABLE IF PO VALUE LESS THAN SR.20,000.00) | C22: Each | D22: 1 | E22: =ROUNDUP(H22*$J$2,0) -> 510 | F22: =D22*E22 -> 510 | G22: شبكة MATV | H22: =K22 -> 510 | I22: Sapling | K22: =L22+M22+N22+O22+P22 -> 510 | M22: 500 | N22: 10 | Q22: رسوم توثيق ومعالجة الطلبات الصغيرة
A23: 16.18.5 | B23: INSTATLLATION | C23: Lot | D23: 1 | E23: =ROUNDUP(H23*$J$2,0) -> 14000 | F23: =D23*E23 -> 14000 | G23: شبكة MATV | H23: =K23 -> 14000 | I23: System Integrator | K23: =L23+M23+N23+O23+P23 -> 14000 | M23: 14000 | Q23: تكاليف التركيب الكامل للنظام
H24: =K24 -> 0 | K24: =L24+M24+N24+O24+P24 -> 0
A26: 16.19 | B26: DIGITAL SIGNAGE SYSTEM : | G26: نظام اللافتات الرقمية Digital Signage
B27: Supply, installations, testing and commissioning of Digital signage system work including cables, conduits, power supply + connections, poe switches and all related complete accessories & work as per Drawing, Specification and Engineer Instructions.
A28: 16.19.1 | B28: WAITING AREA 55" 100% | C28: Each | D28: 6 | E28: =ROUNDUP(H28*$J$2,0) -> 5320 | F28: =D28*E28 -> 31920 | G28: اللافتات الرقمية | H28: =K28 -> 5320 | I28: Samsung | K28: =L28+M28+N28+O28+P28 -> 5320 | M28: 5200 | N28: 100 | P28: 20 | Q28: شاشة عرض رقمية 55" لمنطقة الانتظار (توريد) | R28: شاشة عرض 55 بوصة لمنطقة الانتظار
A29: 16.19.2 | B29: BRACKET 100% | C29: Each | D29: 6 | E29: =ROUNDUP(H29*$J$2,0) -> 985 | F29: =D29*E29 -> 5910 | G29: اللافتات الرقمية | H29: =K29 -> 985 | I29: Peerless-AV | K29: =L29+M29+N29+O29+P29 -> 985 | M29: 975 | N29: 5 | P29: 5 | Q29: حامل/قوس للشاشة 55" لمنطقة الانتظار | R29: حامل تثبيت للشاشة في منطقة الانتظار
A30: 16.19.3 | B30: OPERATIONAL DISPLAY 55" OD | C30: Each | D30: 2 | E30: =ROUNDUP(H30*$J$2,0) -> 4970 | F30: =D30*E30 -> 9940 | G30: اللافتات الرقمية | H30: =K30 -> 4970 | I30: Samsung | K30: =L30+M30+N30+O30+P30 -> 4970 | M30: 4850 | N30: 100 | P30: 20 | Q30: شاشة عرض تشغيلية 55" (توريد) | R30: شاشة تشغيل 55 بوصة للمناطق التشغيلية
A31: 16.19.4 | B31: BRACKET | C31: Each | D31: 2 | E31: =ROUNDUP(H31*$J$2,0) -> 985 | F31: =D31*E31 -> 1970 | G31: اللافتات الرقمية | H31: =K31 -> 985 | I31: Peerless-AV | K31: =L31+M31+N31+O31+P31 -> 985 | M31: 975 | N31: 5 | P31: 5 | Q31: حامل/قوس لشاشة العرض التشغيلية 55" | R31: حامل تثبيت لشاشة التشغيل
A32: 16.19.5 | B32: DIRECTORy LISTING SCREEN 55" | C32: Each | D32: 2 | E32: =ROUNDUP(H32*$J$2,0) -> 4770 | F32: =D32*E32 -> 9540 | G32: اللافتات الرقمية | H32: =K32 -> 4770 | I32: Samsung | K32: =L32+M32+N32+O32+P32 -> 4770 | M32: 4650 | N32: 100 | P32: 20 | Q32: شاشة دليل/قائمة 55" (توريد) | R32: شاشة عرض دليل الأقسام 55 بوصة
A33: 16.19.6 | B33: BRACKET | C33: Each | D33: 2 | E33: =ROUNDUP(H33*$J$2,0) -> 985 | F33: =D33*E33 -> 1970 | G33: اللافتات الرقمية | H33: =K33 -> 985 | I33: Peerless-AV | K33: =L33+M33+N33+O33+P33 -> 985 | M33: 975 | N33: 5 | P33: 5 | Q33: حامل/قوس لشاشة الدليل 55" | R33: حامل تثبيت لشاشة دليل الأقسام
A34: 16.19.7 | B34: Conduiting, Cable pulling of data and power socket, installation of Face plate for data outlet and power socket for COUNTER TOUCH SCREEN 13" | C34: Each | D34: 7 | E34: =ROUNDUP(H34*$J$2,0) -> 1005 | F34: =D34*E34 -> 7035 | G34: اللافتات الرقمية | H34: =K34 -> 1005 | I34: Samsung | K34: =L34+M34+N34+O34+P34 -> 1005 | M34: 800 | N34: 5 | P34: 200 | Q34: تمديد مواسير وكابلات سحب بيانات ومقبس طاقة، وتركيب لوحة وجه لمخرج البيانات ومقبس الطاقة لشاشة اللمس COUNTER 13" | R34: تمديد مواسير وسحب كابلات وتركيب فيش بيانات وكهرباء لشاشة الكاونتر 13 بوصة
A35: 16.19.8 | B35: DOCTOR TOUCH SCREEN 13" | C35: Each | D35: 31 | E35: =ROUNDUP(H35*$J$2,0) -> 2460 | F35: =D35*E35 -> 76260 | G35: اللافتات الرقمية | H35: =K35 -> 2460 | I35: Dell | K35: =L35+M35+N35+O35+P35 -> 2460 | M35: 2450 | N35: 5 | P35: 5 | Q35: شاشة لمس للطبيب 13" (توريد) | R35: شاشة لمس للطبيب 13 بوصة
A36: 16.19.9 | B36: STAFF SCREEN 55" | C36: Each | D36: 1 | E36: =ROUNDUP(H36*$J$2,0) -> 4970 | F36: =D36*E36 -> 4970 | G36: اللافتات الرقمية | H36: =K36 -> 4970 | I36: Samsung | K36: =L36+M36+N36+O36+P36 -> 4970 | M36: 4850 | N36: 100 | P36: 20 | Q36: شاشة موظف 55" (توريد) | R36: شاشة عرض 55 بوصة للموظفين
A37: 16.19.10 | B37: BRACKET | C37: Each | D37: 1 | E37: =ROUNDUP(H37*$J$2,0) -> 1000 | F37: =D37*E37 -> 1000 | G37: اللافتات الرقمية | H37: =K37 -> 1000 | I37: Samsung | K37: =L37+M37+N37+O37+P37 -> 1000 | M37: 975 | N37: 5 | P37: 20 | Q37: حامل/قوس لشاشة الموظف 55" | R37: حامل تثبيت لشاشة الموظفين
A38: 16.19.11 | B38: OPERTIONAL SCREEN 55" | C38: Each | D38: 1 | E38: =ROUNDUP(H38*$J$2,0) -> 4970 | F38: =D38*E38 -> 4970 | G38: اللافتات الرقمية | H38: =K38 -> 4970 | I38: Samsung | K38: =L38+M38+N38+O38+P38 -> 4970 | M38: 4850 | N38: 100 | P38: 20 | Q38: شاشة تشغيلية 55" (توريد) | R38: شاشة تشغيل 55 بوصة إضافية
A39: 16.19.12 | B39: BRACKET | C39: Each | D39: 1 | E39: =ROUNDUP(H39*$J$2,0) -> 985 | F39: =D39*E39 -> 985 | G39: اللافتات الرقمية | H39: =K39 -> 985 | I39: Samsung | K39: =L39+M39+N39+O39+P39 -> 985 | M39: 975 | N39: 5 | P39: 5 | Q39: حامل/قوس للشاشة التشغيلية 55" | R39: حامل تثبيت للشاشة التشغيلية
A40: 16.19.13 | B40: SOFTWARE | C40: LS | D40: 1 | E40: =ROUNDUP(H40*$J$2,0) -> 25000 | F40: =D40*E40 -> 25000 | G40: اللافتات الرقمية | H40: =K40 -> 25000 | I40: Scala / Samsung MagicINFO | K40: =L40+M40+N40+O40+P40 -> 25000 | M40: 25000 | Q40: برنامج نظام العرض الرقمي (ترخيص / سيرفر / CMS) | R40: برنامج إدارة المحتوى الرقمي للشاشات
A41: 16.19.14 | B41: Installation Charges | C41: LOT | D41: 1 | E41: =ROUNDUP(H41*$J$2,0) -> 15000 | F41: =D41*E41 -> 15000 | G41: اللافتات الرقمية | H41: =K41 -> 15000 | I41: System Integrator | K41: 15000 | Q41: رسوم تركيب نظام العرض الرقمي (قيمة شاملة) | R41: تكاليف التركيب والتوصيل الكامل للنظام
A43: 16.2 | B43: Access Control System | G43: نظام التحكم بالدخول Access Control
B44: Supply, installations, testing and commissioning of Access Control system work including cables, conduits, power supply + connections and all related complete accessories & work as per Drawing, Specification and Engineer Instructions.
...

Sheet Low Current-missing
A2: Low Current | J2: 1
A3: Item No. | B3: Description | C3: Unit | D3: Qty | E3: Unit Price (SR) | F3: Amount ( SR ) | G3: العام | H3: Best | I3: Supplier | J3: O&P% | K3: Dry (O) | L3: OUTLET (P) | M3: Supply (Q) | N3: Wastage (R) | O3: Install (S) | P3: Access (T) | Q3: ملاحظات | R3: الموردون
A5: 16.18 | B5: MATV SYSTEM : | G5: نظام MATV
B6: Supply, installations, testing and commissioning of MATV systems work including cables, conduits, power supply + connections and all related complete accessories & work as per Drawing, Specification and Engineer Instructions.
A7: 16.18-1 | B7: MATV Points (Conduing with Accessories) | C7: Lm | D7: 850 | E7: =ROUNDUP(H7*$J$2,0) -> 19 | F7: =D7*E7 -> 16150 | G7: نظام MATV | H7: =K7 -> 19 | I7: Generic / Local | K7: =L7+M7+N7+O7+P7 -> 19 | M7: 15 | N7: 1 | P7: 3
A8: 16.18-2 | B8: MATV Cables | C8: Lm | D8: 1200 | E8: =ROUNDUP(H8*$J$2,0) -> 19 | F8: =D8*E8 -> 22800 | G8: نظام MATV | H8: =K8 -> 19 | I8: Generic / Local | K8: =L8+M8+N8+O8+P8 -> 19 | M8: 15 | N8: 1 | P8: 3
A9: 16.18-3 | B9: RF Amplifier | C9: No | D9: 2 | E9: =ROUNDUP(H9*$J$2,0) -> 1970 | F9: =D9*E9 -> 3940 | G9: نظام MATV | H9: =K9 -> 1970 | I9: Generic | K9: =L9+M9+N9+O9+P9 -> 1970 | M9: 1900 | N9: 20 | P9: 50
A10: 16.18-4 | B10: 1 into 8 RF splitter | C10: No | D10: 2 | E10: =ROUNDUP(H10*$J$2,0) -> 305 | F10: =D10*E10 -> 610 | G10: نظام MATV | H10: =K10 -> 305 | I10: Generic | K10: =L10+M10+N10+O10+P10 -> 305 | M10: 285 | N10: 5 | P10: 15
A11: 16.18-5 | B11: TV outlet for RF | C11: No | D11: 10 | E11: =ROUNDUP(H11*$J$2,0) -> 140 | F11: =D11*E11 -> 1400 | G11: نظام MATV | H11: =K11 -> 140 | I11: Generic | K11: =L11+M11+N11+O11+P11 -> 140 | M11: 125 | N11: 5 | P11: 10
A12: 16.18-6 | B12: Power Supply for Amplifier | C12: No. | D12: 2 | E12: =ROUNDUP(H12*$J$2,0) -> 493 | F12: =D12*E12 -> 986 | G12: نظام MATV | H12: =K12 -> 493 | I12: Generic | K12: =L12+M12+N12+O12+P12 -> 493 | M12: 485 | N12: 5 | P12: 3
A13: 16.18-7 | B13: Samsung , 50 inch , Smart screen | C13: No. | D13: 4 | E13: =ROUNDUP(H13*$J$2,0) -> 2210 | F13: =D13*E13 -> 8840 | G13: نظام MATV | H13: =K13 -> 2210 | I13: Samsung | K13: =L13+M13+N13+O13+P13 -> 2210 | M13: 2100 | N13: 100 | P13: 10
A14: 16.18-8 | B14: Samsung , 70 inch , Smart Screen | C14: No. | D14: 2 | E14: =ROUNDUP(H14*$J$2,0) -> 2710 | F14: =D14*E14 -> 5420 | G14: نظام MATV | H14: =K14 -> 2710 | I14: Samsung | K14: =L14+M14+N14+O14+P14 -> 2710 | M14: 2500 | N14: 200 | P14: 10
A15: 16.18-9 | B15: Testing & Commissioning | C15: LS | D15: 1 | E15: =ROUNDUP(H15*$J$2,0) -> 5000 | F15: =D15*E15 -> 5000 | G15: نظام MATV | H15: =K15 -> 5000 | I15: System Integrator | K15: =L15+M15+N15+O15+P15 -> 5000 | M15: 5000
A17: 16.19 | B17: SECURITY / CCTV SYSTEM : | G17: نظام SECURITY / CCTV SYSTEM
B18: Supply, installations, testing and commissioning of CCTV systems work including cables, conduits, power supply + connections and licences with surveillance software, storage server and poe switches and all related complete accessories & work as per Drawing, Specification and Engineer Instructions.
A19: 16.19-1 | B19: CCTV Points (Conduing with Accessories) | C19: Lm | D19: 560 | E19: =ROUNDUP(H19*$J$2,0) -> 19 | F19: =D19*E19 -> 10640 | G19: نظام CCTV SYSTEM | H19: =K19 -> 19 | I19: Generic / Local | K19: =L19+M19+N19+O19+P19 -> 19 | M19: 15 | N19: 1 | P19: 3
A20: 16.19-2 | B20: CCTV CAT6A Cables | C20: Lm | D20: 800 | E20: =ROUNDUP(H20*$J$2,0) -> 19 | F20: =D20*E20 -> 15200 | G20: نظام CCTV SYSTEM | H20: =K20 -> 19 | I20: Generic / Local | K20: =L20+M20+N20+O20+P20 -> 19 | M20: 15 | N20: 1 | P20: 3
A21: 16.19-3 | B21: Dome Camera (FIXED) | C21: No | D21: 8 | E21: =ROUNDUP(H21*$J$2,0) -> 703 | F21: =D21*E21 -> 5624 | G21: نظام CCTV SYSTEM | H21: =K21 -> 703 | I21: Hikvision / Dahua | K21: =L21+M21+N21+O21+P21 -> 703 | M21: 685 | N21: 10 | P21: 8
A22: 16.19-4 | B22: Bullet Camera (FIXED) | C22: No | D22: 4 | E22: =ROUNDUP(H22*$J$2,0) -> 613 | F22: =D22*E22 -> 2452 | G22: نظام CCTV SYSTEM | H22: =K22 -> 613 | I22: Hikvision / Dahua | K22: =L22+M22+N22+O22+P22 -> 613 | M22: 595 | N22: 10 | P22: 8
A23: 16.19-5 | B23: WorkStation | C23: No | D23: 1 | E23: =ROUNDUP(H23*$J$2,0) -> 4700 | F23: =D23*E23 -> 4700 | G23: نظام CCTV SYSTEM | H23: =K23 -> 4700 | I23: Dell / HP | K23: =L23+M23+N23+O23+P23 -> 4700 | M23: 4500 | N23: 100 | P23: 100
A24: 16.19-6 | B24: NVR with license | C24: No | D24: 1 | E24: =ROUNDUP(H24*$J$2,0) -> 4000 | F24: =D24*E24 -> 4000 | G24: نظام CCTV SYSTEM | H24: =K24 -> 4000 | I24: Hikvision / Dahua | K24: =L24+M24+N24+O24+P24 -> 4000 | M24: 3850 | N24: 50 | P24: 100
A25: 16.19-7 | B25: Cabinet | C25: No | D25: 1 | E25: =ROUNDUP(H25*$J$2,0) -> 3267 | F25: =D25*E25 -> 3267 | G25: نظام CCTV SYSTEM | H25: =K25 -> 3267 | I25: FINOSEL / Generic | K25: =L25+M25+N25+O25+P25 -> 3267 | L25: 317 | M25: 2850 | N25: 50 | P25: 50
A26: 16.19-8 | B26: Hard Disk with miniumum 3 months backup | C26: LS | D26: 1 | E26: =ROUNDUP(H26*$J$2,0) -> 2310 | F26: =D26*E26 -> 2310 | G26: نظام CCTV SYSTEM | H26: =K26 -> 2310 | I26: Seagate / WD | K26: =L26+M26+N26+O26+P26 -> 2310 | M26: 2200 | N26: 100 | P26: 10
A27: 16.19-9 | B27: Configuration, Testing & Commissioning | C27: LS | D27: 1 | E27: =ROUNDUP(H27*$J$2,0) -> 5700 | F27: =D27*E27 -> 5700 | G27: نظام CCTV SYSTEM | H27: =K27 -> 5700 | I27: System Integrator | K27: =L27+M27+N27+O27+P27 -> 5700 | M27: 5500 | N27: 200
G28: نظام CCTV SYSTEM | H28: =K28 -> 0 | K28: =L28+M28+N28+O28+P28 -> 0
A29: 16.18 | B29: MASTER CLOCK SYSTEM : | G29: MASTER CLOCK SYSTEM
B30: Supply, installations, testing and commissioning of Master clock system work including cables, conduits, power supply + connections, poe switches and all related complete accessories & work as per Drawing, Specification and Engineer Instructions. | Q30: يشمل NTP Server و GPS Antenna. ملاحظة: الـ IT بتاع المستشفى مش هيخليك توصل NTP Server على شبكتهم بسهولة، ده هيحتاج أمن سيبراني وتصريحات.
A31: 16.20-1 | B31: Clock Points (Conduing with Accessories) | C31: Lm | D31: 650 | E31: =ROUNDUP(H31*$J$2,0) -> 19 | F31: =D31*E31 -> 12350 | G31: شبكة MATV | H31: =K31 -> 19 | K31: =L31+M31+N31+O31+P31 -> 19 | M31: 15 | N31: 1 | P31: 3
A32: 16.20-2 | B32: Clock System CATA6A Cables | C32: Lm | D32: 1100 | E32: =ROUNDUP(H32*$J$2,0) -> 7 | F32: =D32*E32 -> 7700 | G32: شبكة MATV | H32: =K32 -> 6.5 | K32: =L32+M32+N32+O32+P32 -> 6.5 | M32: 4 | N32: 2 | P32: 0.5
A33: 16.20-3 | B33: Single side digital Clock | C33: No | D33: 8 | E33: =ROUNDUP(H33*$J$2,0) -> 2235 | F33: =D33*E33 -> 17880 | G33: شبكة MATV | H33: =K33 -> 2235 | I33: Sapling | K33: =L33+M33+N33+O33+P33 -> 2235 | M33: 2200 | N33: 20 | P33: 15 | Q33: ساعة رقمية صناعية/حائطية بحجم عرض تجاري (سوق السعودية 2026).
A34: 16.20-4 | B34: Double side digital Clock | C34: No | D34: 8 | E34: =ROUNDUP(H34*$J$2,0) -> 3535 | F34: =D34*E34 -> 28280 | G34: شبكة MATV | H34: =K34 -> 3535 | I34: Sapling | K34: =L34+M34+N34+O34+P34 -> 3535 | M34: 3500 | N34: 20 | P34: 15 | Q34: ساعة رقمية مزدوجة الوجه
A35: 16.20-5 | B35: GPS Antenna | C35: No | D35: 1 | E35: =ROUNDUP(H35*$J$2,0) -> 4535 | F35: =D35*E35 -> 4535 | G35: شبكة MATV | H35: =K35 -> 4535 | I35: Sapling | K35: =L35+M35+N35+O35+P35 -> 4535 | M35: 4500 | N35: 20 | P35: 15 | Q35: أنتين توقيت/GPS تجاري مناسب لأنظمة التزامن؛
A36: 16.20-6 | B36: Configuration, Testing & Commissioning | C36: LS | D36: 1 | E36: =ROUNDUP(H36*$J$2,0) -> 8300 | F36: =D36*E36 -> 8300 | G36: شبكة MATV | H36: =K36 -> 8300 | I36: System Integrator | K36: =L36+M36+N36+O36+P36 -> 8300 | M36: 8000 | N36: 200 | P36: 100
G37: نظام CCTV SYSTEM | H37: =K37 -> 0 | K37: =L37+M37+N37+O37+P37 -> 0
A39: 16.19 | B39: DIGITAL SIGNAGE SYSTEM : | G39: نظام اللافتات الرقمية Digital Signage
B40: Supply, installations, testing and commissioning of Digital signage system work including cables, conduits, power supply + connections, poe switches and all related complete accessories & work as per Drawing, Specification and Engineer Instructions.
A41: 16.21-1 | B41: D.S. Points (Conduing with Accessories) | C41: Lm | D41: 2300 | E41: =ROUNDUP(H41*$J$2,0) -> 19 | F41: =D41*E41 -> 43700 | G41: اللافتات الرقمية | H41: =K41 -> 19 | I41: Samsung | K41: =L41+M41+N41+O41+P41 -> 19 | M41: 15 | N41: 1 | P41: 3
A42: 16.21-2 | B42: D.S CAT6A Cables | C42: Lm | D42: 3900 | E42: =ROUNDUP(H42*$J$2,0) -> 7 | F42: =D42*E42 -> 27300 | G42: اللافتات الرقمية | H42: =K42 -> 6.5 | I42: Samsung | K42: =L42+M42+N42+O42+P42 -> 6.5 | M42: 4 | N42: 2 | P42: 0.5
A43: 16.21-3 | B43: Samsung DB10DDigital Signage with Embbeded | C43: No | D43: 30 | E43: =ROUNDUP(H43*$J$2,0) -> 1460 | F43: =D43*E43 -> 43800 | G43: نظام Digital Signage | H43: =K43 -> 1460 | I43: Samsung | K43: =L43+M43+N43+O43+P43 -> 1460 | M43: 1400 | N43: 50 | P43: 10
A44: 16.21-4 | B44: Bracket wall mount Kit | C44: No | D44: 30 | E44: =ROUNDUP(H44*$J$2,0) -> 190 | F44: =D44*E44 -> 5700 | G44: نظام Digital Signage | H44: =K44 -> 190 | I44: Peerless-AV / Generic | K44: =L44+M44+N44+O44+P44 -> 190 | M44: 185 | N44: 5
...

Sheet Medical Gases
A2: Medical Gas | J2: 1
A3: Item No. | B3: Description | C3: Unit | D3: Qty | E3: Rate | F3: Amount | G3: العام | H3: Best | I3: Supplier | J3: O&P% | K3: Dry (O) | L3: OUTLET (P) | M3: Supply (Q) | N3: Wastage (R) | O3: Install (S) | P3: Access (T) | Q3: ملاحظات | R3: الموردون
A4: 17 | B4: MECHANICAL - MEDICAL GASES
A6: 17.1 | B6: MEDICAL GAS PIPES
B7: Supply& install Medical Grade De-greased copper pipe work and fittings as specified including hangers and supports for the following diameters:
A8: 17.1-1 | B8: 15 mm diameter 100% | C8: Lm | D8: 630
A9: 17.1-2 | B9: 22 mm diameter 100% | C9: Lm | D9: 175
A11: 17.2 | B11: VALVES & OUTLETS .
B12: Supply& install Line Ball valves for medical gases as specified including hangers and supports for the following diameters:
A13: 17.2-1 | B13: 15 mm diameter Valve (100%) | C13: No. | D13: 26
A14: 17.2-2 | B14: 22 mm diameter Valve (100%) | C14: No. | D14: 2
A15: 17.2-3 | B15: supply & Install Medical gas outlet for 02 , MA,VAC, N2O, AGSS (100%) | C15: No. | D15: 48
A16: 17.2-4 | B16: Area Gas Service Unit 3 Gases (100%) | C16: No | D16: 2
A18: 17.3 | B18: BED HEAD UNITS
B19: Supply installation, testing and commissioning of Bed Head Units with accessories
B20: Each Bed Head Unit requires 6 to 10 electrical sockets ( 5 Red colored for UPS) and ( 5 Normal white colored) The sockets must be MK standard (Legrand) surface mounted Each Bed Requires 1RJ45 Data Connector Socket on its BHU access provision Every Bed Head Unit or Bed Side BHU must have 1 cutout 45x45mm for nurse call system Every BHU must have a upper and lower integrated Medical Aluminum Rail of Size 25x10 mm Each Bed Requires 3 to 5 Medical Gases as per requirement Type DIN German Standards
A21: 17.3-1 | B21: Bed Head Units length 1500 mm ( BHU out of scope, rate includes first and second fix only) 100% | C21: No. | D21: 8 | E21: =ROUNDUP(H21*$J$2,0) -> 2850 | F21: =D21*E21 -> 22800 | G21: BED HEAD UNIT | H21: =K21 -> 2850 | K21: =L21+M21+N21+O21+P21 -> 2850 | L21: =(250*8)+400+300 -> 2700 | N21: 100 | P21: 50
A24: 17.4 | B24: MISCELLANEOUS ITEMS
A26: 17.4-1 | B26: Labels/Identification for all Medical Gases Equipment & Piping as per specification. (Stickers) 100% | C26: No. | D26: 1
A28: Total for Medical Gases Works in SAR | F28: =SUM(F4:F27) -> 22800
G29: BED HEAD UNIT | H29: =K29 -> 18000.01 | K29: =L29+M29+N29+O29+P29 -> 18000.01 | L29: 134.5 | M29: 10719.3 | N29: 893.28 | O29: 5359.65 | P29: 893.28

Sheet بريك داون كهرباء
A1: م | B1: رقم البند | C1: وصف البند | D1: الكمية | E1: الوحدة | F1: نوع العلبة | G1: سعر العلبة /وحدة | H1: نوع الماسورة | I1: طول/وحدة (م) | J1: سعر/م | K1: إجمالي ماسورة/وحدة | L1: نوع السلك | M1: طول/وحدة (م.ط | N1: سعر/م.ط | O1: إجمالي سلك/وحدة | P1: تثبيت وتوصيل | Q1: ★الوحدة | R1: ★الإجمالي
A3: ◄ لوحات التوزيع الكهربائية
A4: 1 | B4: 1 | C4: لوحة توزيع عادية DB-N4A-1F كاملة المعدات | D4: 1 | E4: عدد | F4: لوحة / كابينة + داخليات | G4: 11880 | H4: تغذية / مسار | I4: 1 | J4: 1980 | K4: =Table6[[#This Row],[سعر/م]]*Table6[[#This Row],[طول/وحدة (م)]] -> 1980 | L4: سلك داخلي / ترقيم | M4: 1 | N4: 1980 | O4: =Table6[[#This Row],[سعر/م.ط]]*Table6[[#This Row],[طول/وحدة (م.ط]] -> 1980 | P4: 3960 | Q4: =Table6[[#This Row],[تثبيت وتوصيل]]+Table6[[#This Row],[إجمالي سلك/وحدة]]+Table6[[#This Row],[إجمالي ماسورة/وحدة]]+Table6[[#This Row],[سعر العلبة /وحدة]] -> 19800 | R4: =Table6[[#This Row],[★الوحدة]]*Table6[[#This Row],[الكمية]] -> 19800
A5: 2 | B5: 2 | C5: لوحة توزيع عادية DB-N4B-1F | D5: 1 | E5: عدد | F5: لوحة / كابينة + داخليات | G5: 10560 | H5: تغذية / مسار | I5: 1 | J5: 1760 | K5: =Table6[[#This Row],[سعر/م]]*Table6[[#This Row],[طول/وحدة (م)]] -> 1760 | L5: سلك داخلي / ترقيم | M5: 1 | N5: 1760 | O5: =Table6[[#This Row],[سعر/م.ط]]*Table6[[#This Row],[طول/وحدة (م.ط]] -> 1760 | P5: 3520 | Q5: =Table6[[#This Row],[تثبيت وتوصيل]]+Table6[[#This Row],[إجمالي سلك/وحدة]]+Table6[[#This Row],[إجمالي ماسورة/وحدة]]+Table6[[#This Row],[سعر العلبة /وحدة]] -> 17600 | R5: =Table6[[#This Row],[★الوحدة]]*Table6[[#This Row],[الكمية]] -> 17600
A6: 3 | B6: 3 | C6: لوحة إنارة DB-LN4-1F | D6: 1 | E6: عدد | F6: لوحة / كابينة + داخليات | G6: 9240 | H6: تغذية / مسار | I6: 1 | J6: 1540 | K6: =Table6[[#This Row],[سعر/م]]*Table6[[#This Row],[طول/وحدة (م)]] -> 1540 | L6: سلك داخلي / ترقيم | M6: 1 | N6: 1540 | O6: =Table6[[#This Row],[سعر/م.ط]]*Table6[[#This Row],[طول/وحدة (م.ط]] -> 1540 | P6: 3080 | Q6: =Table6[[#This Row],[تثبيت وتوصيل]]+Table6[[#This Row],[إجمالي سلك/وحدة]]+Table6[[#This Row],[إجمالي ماسورة/وحدة]]+Table6[[#This Row],[سعر العلبة /وحدة]] -> 15400 | R6: =Table6[[#This Row],[★الوحدة]]*Table6[[#This Row],[الكمية]] -> 15400
A7: 4 | B7: 4 | C7: لوحة طوارئ DB-LE4-1F | D7: 1 | E7: عدد | F7: لوحة / كابينة + داخليات | G7: 7920 | H7: تغذية / مسار | I7: 1 | J7: 1320 | K7: =Table6[[#This Row],[سعر/م]]*Table6[[#This Row],[طول/وحدة (م)]] -> 1320 | L7: سلك داخلي / ترقيم | M7: 1 | N7: 1320 | O7: =Table6[[#This Row],[سعر/م.ط]]*Table6[[#This Row],[طول/وحدة (م.ط]] -> 1320 | P7: 2640 | Q7: =Table6[[#This Row],[تثبيت وتوصيل]]+Table6[[#This Row],[إجمالي سلك/وحدة]]+Table6[[#This Row],[إجمالي ماسورة/وحدة]]+Table6[[#This Row],[سعر العلبة /وحدة]] -> 13200 | R7: =Table6[[#This Row],[★الوحدة]]*Table6[[#This Row],[الكمية]] -> 13200
A8: 5 | B8: 5 | C8: لوحة توزيع DB-E4-1F | D8: 1 | E8: عدد | F8: لوحة / كابينة + داخليات | G8: 7260 | H8: تغذية / مسار | I8: 1 | J8: 1210 | K8: =Table6[[#This Row],[سعر/م]]*Table6[[#This Row],[طول/وحدة (م)]] -> 1210 | L8: سلك داخلي / ترقيم | M8: 1 | N8: 1210 | O8: =Table6[[#This Row],[سعر/م.ط]]*Table6[[#This Row],[طول/وحدة (م.ط]] -> 1210 | P8: 2420 | Q8: =Table6[[#This Row],[تثبيت وتوصيل]]+Table6[[#This Row],[إجمالي سلك/وحدة]]+Table6[[#This Row],[إجمالي ماسورة/وحدة]]+Table6[[#This Row],[سعر العلبة /وحدة]] -> 12100 | R8: =Table6[[#This Row],[★الوحدة]]*Table6[[#This Row],[الكمية]] -> 12100
A9: 6 | B9: 6 | C9: لوحة توزيع DB-U3-1F | D9: 1 | E9: عدد | F9: لوحة / كابينة + داخليات | G9: 6270 | H9: تغذية / مسار | I9: 1 | J9: 1045 | K9: =Table6[[#This Row],[سعر/م]]*Table6[[#This Row],[طول/وحدة (م)]] -> 1045 | L9: سلك داخلي / ترقيم | M9: 1 | N9: 1045 | O9: =Table6[[#This Row],[سعر/م.ط]]*Table6[[#This Row],[طول/وحدة (م.ط]] -> 1045 | P9: 2090 | Q9: =Table6[[#This Row],[تثبيت وتوصيل]]+Table6[[#This Row],[إجمالي سلك/وحدة]]+Table6[[#This Row],[إجمالي ماسورة/وحدة]]+Table6[[#This Row],[سعر العلبة /وحدة]] -> 10450 | R9: =Table6[[#This Row],[★الوحدة]]*Table6[[#This Row],[الكمية]] -> 10450
A10: 7 | B10: 7 | C10: لوحة إنارة DB-LU2-1F | D10: 1 | E10: عدد | F10: لوحة / كابينة + داخليات | G10: 5610 | H10: تغذية / مسار | I10: 1 | J10: 935 | K10: =Table6[[#This Row],[سعر/م]]*Table6[[#This Row],[طول/وحدة (م)]] -> 935 | L10: سلك داخلي / ترقيم | M10: 1 | N10: 935 | O10: =Table6[[#This Row],[سعر/م.ط]]*Table6[[#This Row],[طول/وحدة (م.ط]] -> 935 | P10: 1870 | Q10: =Table6[[#This Row],[تثبيت وتوصيل]]+Table6[[#This Row],[إجمالي سلك/وحدة]]+Table6[[#This Row],[إجمالي ماسورة/وحدة]]+Table6[[#This Row],[سعر العلبة /وحدة]] -> 9350 | R10: =Table6[[#This Row],[★الوحدة]]*Table6[[#This Row],[الكمية]] -> 9350
A11: 8 | B11: 8 | C11: لوحة تحكم إنارة KNX LCP4-1F | D11: 1 | E11: عدد | F11: لوحة / كابينة + داخليات | G11: 14520 | H11: تغذية / مسار | I11: 1 | J11: 2420 | K11: =Table6[[#This Row],[سعر/م]]*Table6[[#This Row],[طول/وحدة (م)]] -> 2420 | L11: سلك داخلي / ترقيم | M11: 1 | N11: 2420 | O11: =Table6[[#This Row],[سعر/م.ط]]*Table6[[#This Row],[طول/وحدة (م.ط]] -> 2420 | P11: 4840 | Q11: =Table6[[#This Row],[تثبيت وتوصيل]]+Table6[[#This Row],[إجمالي سلك/وحدة]]+Table6[[#This Row],[إجمالي ماسورة/وحدة]]+Table6[[#This Row],[سعر العلبة /وحدة]] -> 24200 | R11: =Table6[[#This Row],[★الوحدة]]*Table6[[#This Row],[الكمية]] -> 24200
A13: ◄ الكابلات والأسلاك
A14: 9 | B14: 9 | C14: كابل 4C-10مم² CU/XLPE/PVC LS0H 0.6/1.0kV | D14: 1000 | E14: م.ط | F14: توريد كابل | G14: 51.425 | H14: حماية / مسار | I14: 1 | J14: 3.025 | K14: =Table6[[#This Row],[سعر/م]]*Table6[[#This Row],[طول/وحدة (م)]] -> 3.025 | L14: نهايات | M14: 1 | N14: 3.025 | O14: =Table6[[#This Row],[سعر/م.ط]]*Table6[[#This Row],[طول/وحدة (م.ط]] -> 3.025 | P14: 3.025
A15: 10 | B15: 10 | C15: كابل 4C-35مم² CU/XLPE/PVC LS0H | D15: 1000 | E15: م.ط | F15: توريد كابل | G15: 172.975 | H15: حماية / مسار | I15: 1 | J15: 10.175 | K15: =Table6[[#This Row],[سعر/م]]*Table6[[#This Row],[طول/وحدة (م)]] -> 10.175 | L15: نهايات | M15: 1 | N15: 10.175 | O15: =Table6[[#This Row],[سعر/م.ط]]*Table6[[#This Row],[طول/وحدة (م.ط]] -> 10.175 | P15: 10.175
A16: 11 | B16: 11 | C16: كابل 4C-50مم² CU/XLPE/PVC LS0H | D16: 400 | E16: م.ط | F16: توريد كابل | G16: 243.1 | H16: حماية / مسار | I16: 1 | J16: 14.3 | K16: =Table6[[#This Row],[سعر/م]]*Table6[[#This Row],[طول/وحدة (م)]] -> 14.3 | L16: نهايات | M16: 1 | N16: 14.3 | O16: =Table6[[#This Row],[سعر/م.ط]]*Table6[[#This Row],[طول/وحدة (م.ط]] -> 14.3 | P16: 14.3
A17: 12 | B17: 12 | C17: كابل أرضي 1C-10مم² أصفر/أخضر | D17: 1000 | E17: م.ط | F17: توريد كابل | G17: 16.83 | H17: حماية / مسار | I17: 1 | J17: 0.99 | K17: =Table6[[#This Row],[سعر/م]]*Table6[[#This Row],[طول/وحدة (م)]] -> 0.99 | L17: نهايات | M17: 1 | N17: 0.99 | O17: =Table6[[#This Row],[سعر/م.ط]]*Table6[[#This Row],[طول/وحدة (م.ط]] -> 0.99 | P17: 0.99
A18: 13 | B18: 13 | C18: كابل أرضي 1C-16مم² | D18: 1000 | E18: م.ط | F18: توريد كابل | G18: 26.18 | H18: حماية / مسار | I18: 1 | J18: 1.54 | K18: =Table6[[#This Row],[سعر/م]]*Table6[[#This Row],[طول/وحدة (م)]] -> 1.54 | L18: نهايات | M18: 1 | N18: 1.54 | O18: =Table6[[#This Row],[سعر/م.ط]]*Table6[[#This Row],[طول/وحدة (م.ط]] -> 1.54 | P18: 1.54
A19: 14 | B19: 14 | C19: كابل أرضي 1C-25مم² | D19: 400 | E19: م.ط | F19: توريد كابل | G19: 39.27 | H19: حماية / مسار | I19: 1 | J19: 2.31 | K19: =Table6[[#This Row],[سعر/م]]*Table6[[#This Row],[طول/وحدة (م)]] -> 2.31 | L19: نهايات | M19: 1 | N19: 2.31 | O19: =Table6[[#This Row],[سعر/م.ط]]*Table6[[#This Row],[طول/وحدة (م.ط]] -> 2.31 | P19: 2.31
A20: 15 | B20: 15 | C20: Cable Lugs Glands & Terminations | D20: 1 | E20: LS | F20: توريد كابل | G20: 7480 | H20: حماية / مسار | I20: 1 | J20: 440 | K20: =Table6[[#This Row],[سعر/م]]*Table6[[#This Row],[طول/وحدة (م)]] -> 440 | L20: نهايات | M20: 1 | N20: 440 | O20: =Table6[[#This Row],[سعر/م.ط]]*Table6[[#This Row],[طول/وحدة (م.ط]] -> 440 | P20: 440
A22: ◄ مخارج القوى والأفياش
A23: 16 | B23: 16 | C23: Power Points Conduit+Wire+Box 4مم² شاملة | D23: 327 | E23: عدد
A24: 17 | B24: 17 | C24: مفتاح إنارة أحادي 1G1W | D24: 100 | E24: عدد | F24: علبة بلاستيك | G24: 9 | H24: ماسورة / ترنك | I24: 5 | J24: 3 | K24: =Table6[[#This Row],[سعر/م]]*Table6[[#This Row],[طول/وحدة (م)]] -> 15 | L24: سلك تغذية | M24: =Table6[[#This Row],[طول/وحدة (م)]]*1.1 -> 5.5 | N24: 12 | O24: =Table6[[#This Row],[سعر/م.ط]]*Table6[[#This Row],[طول/وحدة (م.ط]] -> 66 | P24: 80 | Q24: =Table6[[#This Row],[تثبيت وتوصيل]]+Table6[[#This Row],[إجمالي سلك/وحدة]]+Table6[[#This Row],[إجمالي ماسورة/وحدة]]+Table6[[#This Row],[سعر العلبة /وحدة]] -> 170 | R24: =Table6[[#This Row],[★الوحدة]]*Table6[[#This Row],[الكمية]] -> 17000
A25: 18 | B25: 18 | C25: مفتاح إنارة ثنائي 2G1W | D25: 20 | E25: عدد | F25: علبة بلاستيك | G25: 9 | H25: ماسورة / ترنك | I25: 10 | J25: 3 | K25: =Table6[[#This Row],[سعر/م]]*Table6[[#This Row],[طول/وحدة (م)]] -> 30 | L25: سلك تغذية | M25: =Table6[[#This Row],[طول/وحدة (م)]]*1.1 -> 11 | N25: 12 | O25: =Table6[[#This Row],[سعر/م.ط]]*Table6[[#This Row],[طول/وحدة (م.ط]] -> 132 | P25: 80 | Q25: =Table6[[#This Row],[تثبيت وتوصيل]]+Table6[[#This Row],[إجمالي سلك/وحدة]]+Table6[[#This Row],[إجمالي ماسورة/وحدة]]+Table6[[#This Row],[سعر العلبة /وحدة]] -> 251 | R25: =Table6[[#This Row],[★الوحدة]]*Table6[[#This Row],[الكمية]] -> 5020
A26: 19 | B26: 19 | C26: Single Socket 13A Berker 1G | D26: 130 | E26: عدد | F26: علبة بلاستيك | G26: 9 | H26: ماسورة / ترنك | I26: 5 | J26: 3 | K26: =Table6[[#This Row],[سعر/م]]*Table6[[#This Row],[طول/وحدة (م)]] -> 15 | L26: سلك تغذية | M26: =Table6[[#This Row],[طول/وحدة (م)]]*1.1 -> 5.5 | N26: 12 | O26: =Table6[[#This Row],[سعر/م.ط]]*Table6[[#This Row],[طول/وحدة (م.ط]] -> 66 | P26: 80 | Q26: =Table6[[#This Row],[تثبيت وتوصيل]]+Table6[[#This Row],[إجمالي سلك/وحدة]]+Table6[[#This Row],[إجمالي ماسورة/وحدة]]+Table6[[#This Row],[سعر العلبة /وحدة]] -> 170 | R26: =Table6[[#This Row],[★الوحدة]]*Table6[[#This Row],[الكمية]] -> 22100
A27: 20 | B27: 20 | C27: Duplex Socket 13A Berker 1G | D27: 70 | E27: عدد | F27: علبة بلاستيك | G27: 9 | H27: ماسورة / ترنك | I27: 5 | J27: 3 | K27: =Table6[[#This Row],[سعر/م]]*Table6[[#This Row],[طول/وحدة (م)]] -> 15 | L27: سلك تغذية | M27: =Table6[[#This Row],[طول/وحدة (م)]]*1.1 -> 5.5 | N27: 12 | O27: =Table6[[#This Row],[سعر/م.ط]]*Table6[[#This Row],[طول/وحدة (م.ط]] -> 66 | P27: 80 | Q27: =Table6[[#This Row],[تثبيت وتوصيل]]+Table6[[#This Row],[إجمالي سلك/وحدة]]+Table6[[#This Row],[إجمالي ماسورة/وحدة]]+Table6[[#This Row],[سعر العلبة /وحدة]] -> 170 | R27: =Table6[[#This Row],[★الوحدة]]*Table6[[#This Row],[الكمية]] -> 11900
A28: 21 | B28: 21 | C28: Industrial Low Voltage Socket 5-pin 30A IP67 | D28: 5 | E28: عدد | F28: علبة بلاستيك | G28: 9 | H28: ماسورة / ترنك | I28: 15 | J28: 3 | K28: =Table6[[#This Row],[سعر/م]]*Table6[[#This Row],[طول/وحدة (م)]] -> 45 | L28: كابل تغذية | M28: =Table6[[#This Row],[طول/وحدة (م)]]*1.1 -> 16.5 | N28: 20 | O28: =Table6[[#This Row],[سعر/م.ط]]*Table6[[#This Row],[طول/وحدة (م.ط]] -> 330 | P28: 130 | Q28: =Table6[[#This Row],[تثبيت وتوصيل]]+Table6[[#This Row],[إجمالي سلك/وحدة]]+Table6[[#This Row],[إجمالي ماسورة/وحدة]]+Table6[[#This Row],[سعر العلبة /وحدة]] -> 514 | R28: =Table6[[#This Row],[★الوحدة]]*Table6[[#This Row],[الكمية]] -> 2570
A29: 22 | B29: 22 | C29: Floor Box Recessed 2 Compartments Push Open | D29: 2 | E29: عدد | F29: علبة أرضية معدنية مع غطاء مفصلي | H29: ماسورة / ترنك | I29: 8 | J29: 3 | K29: =Table6[[#This Row],[سعر/م]]*Table6[[#This Row],[طول/وحدة (م)]] -> 24 | L29: سلك تغذية | M29: =Table6[[#This Row],[طول/وحدة (م)]]*1.1 -> 8.8 | N29: 12 | O29: =Table6[[#This Row],[سعر/م.ط]]*Table6[[#This Row],[طول/وحدة (م.ط]] -> 105.6 | P29: 150 | Q29: =Table6[[#This Row],[تثبيت وتوصيل]]+Table6[[#This Row],[إجمالي سلك/وحدة]]+Table6[[#This Row],[إجمالي ماسورة/وحدة]]+Table6[[#This Row],[سعر العلبة /وحدة]] -> 279.6 | R29: =Table6[[#This Row],[★الوحدة]]*Table6[[#This Row],[الكمية]] -> 559.2
A30: 23 | B30: 23 | C30: Isolator 32A Three Pole + Neutral | D30: 20 | E30: عدد | F30: علبة بلاستيك | G30: 9 | H30: ماسورة / ترنك | I30: 15 | J30: 3 | K30: =Table6[[#This Row],[سعر/م]]*Table6[[#This Row],[طول/وحدة (م)]] -> 45 | L30: كابل تغذية | M30: =Table6[[#This Row],[طول/وحدة (م)]]*1.1 -> 16.5 | N30: 20 | O30: =Table6[[#This Row],[سعر/م.ط]]*Table6[[#This Row],[طول/وحدة (م.ط]] -> 330 | P30: 150 | Q30: =Table6[[#This Row],[تثبيت وتوصيل]]+Table6[[#This Row],[إجمالي سلك/وحدة]]+Table6[[#This Row],[إجمالي ماسورة/وحدة]]+Table6[[#This Row],[سعر العلبة /وحدة]] -> 534 | R30: =Table6[[#This Row],[★الوحدة]]*Table6[[#This Row],[الكمية]] -> 10680
A32: ◄ نظام الإنارة
A33: 24 | B33: 24 | C33: Lighting Points Conduit+Wire+Box 2.5مم² | D33: 284 | E33: عدد | F33: علبة بلاستيك | G33: 9 | H33: PVC | I33: 5 | J33: 3 | K33: =Table6[[#This Row],[سعر/م]]*Table6[[#This Row],[طول/وحدة (م)]] -> 15 | L33: سلك إنارة | M33: =Table6[[#This Row],[طول/وحدة (م)]]*1.1 -> 5.5 | N33: 9 | O33: =Table6[[#This Row],[سعر/م.ط]]*Table6[[#This Row],[طول/وحدة (م.ط]] -> 49.5 | P33: 80 | Q33: =Table6[[#This Row],[تثبيت وتوصيل]]+Table6[[#This Row],[إجمالي سلك/وحدة]]+Table6[[#This Row],[إجمالي ماسورة/وحدة]]+Table6[[#This Row],[سعر العلبة /وحدة]] -> 153.5 | R33: =Table6[[#This Row],[★الوحدة]]*Table6[[#This Row],[الكمية]] -> 43594
A34: 25 | B34: 25 | C34: Type-L1 Square Downlight 23W IP44 230V | D34: 80 | E34: عدد | F34: علبة بلاستيك | G34: 9 | H34: PVC | I34: 5 | J34: 3 | K34: =Table6[[#This Row],[سعر/م]]*Table6[[#This Row],[طول/وحدة (م)]] -> 15 | L34: سلك إنارة | M34: =Table6[[#This Row],[طول/وحدة (م)]]*1.1 -> 5.5 | N34: 9 | O34: =Table6[[#This Row],[سعر/م.ط]]*Table6[[#This Row],[طول/وحدة (م.ط]] -> 49.5 | P34: 80 | Q34: =Table6[[#This Row],[تثبيت وتوصيل]]+Table6[[#This Row],[إجمالي سلك/وحدة]]+Table6[[#This Row],[إجمالي ماسورة/وحدة]]+Table6[[#This Row],[سعر العلبة /وحدة]] -> 153.5 | R34: =Table6[[#This Row],[★الوحدة]]*Table6[[#This Row],[الكمية]] -> 12280
A35: 26 | B35: 26 | C35: Type-L2 Square Panel Downlight 16W IP44 5000K | D35: 20 | E35: عدد | F35: علبة بلاستيك | G35: 9 | H35: PVC | I35: 5 | J35: 3 | K35: =Table6[[#This Row],[سعر/م]]*Table6[[#This Row],[طول/وحدة (م)]] -> 15 | L35: سلك إنارة | M35: =Table6[[#This Row],[طول/وحدة (م)]]*1.1 -> 5.5 | N35: 9 | O35: =Table6[[#This Row],[سعر/م.ط]]*Table6[[#This Row],[طول/وحدة (م.ط]] -> 49.5 | P35: 80 | Q35: =Table6[[#This Row],[تثبيت وتوصيل]]+Table6[[#This Row],[إجمالي سلك/وحدة]]+Table6[[#This Row],[إجمالي ماسورة/وحدة]]+Table6[[#This Row],[سعر العلبة /وحدة]] -> 153.5 | R35: =Table6[[#This Row],[★الوحدة]]*Table6[[#This Row],[الكمية]] -> 3070
A36: 27 | B36: 27 | C36: Type-L3 Square Spot 5W IP23 3000K | D36: 20 | E36: عدد | F36: علبة بلاستيك | G36: 9 | H36: PVC | I36: 5 | J36: 3 | K36: =Table6[[#This Row],[سعر/م]]*Table6[[#This Row],[طول/وحدة (م)]] -> 15 | L36: سلك إنارة | M36: =Table6[[#This Row],[طول/وحدة (م)]]*1.1 -> 5.5 | N36: 9 | O36: =Table6[[#This Row],[سعر/م.ط]]*Table6[[#This Row],[طول/وحدة (م.ط]] -> 49.5 | P36: 80 | Q36: =Table6[[#This Row],[تثبيت وتوصيل]]+Table6[[#This Row],[إجمالي سلك/وحدة]]+Table6[[#This Row],[إجمالي ماسورة/وحدة]]+Table6[[#This Row],[سعر العلبة /وحدة]] -> 153.5 | R36: =Table6[[#This Row],[★الوحدة]]*Table6[[#This Row],[الكمية]] -> 3070
A37: 28 | B37: 28 | C37: Type-L7 Circular Downlight 10.5W IP45 4000K | D37: 20 | E37: عدد | F37: علبة بلاستيك | G37: 9 | H37: PVC | I37: 5 | J37: 3 | K37: =Table6[[#This Row],[سعر/م]]*Table6[[#This Row],[طول/وحدة (م)]] -> 15 | L37: سلك إنارة | M37: =Table6[[#This Row],[طول/وحدة (م)]]*1.1 -> 5.5 | N37: 9 | O37: =Table6[[#This Row],[سعر/م.ط]]*Table6[[#This Row],[طول/وحدة (م.ط]] -> 49.5 | P37: 80 | Q37: =Table6[[#This Row],[تثبيت وتوصيل]]+Table6[[#This Row],[إجمالي سلك/وحدة]]+Table6[[#This Row],[إجمالي ماسورة/وحدة]]+Table6[[#This Row],[سعر العلبة /وحدة]] -> 153.5 | R37: =Table6[[#This Row],[★الوحدة]]*Table6[[#This Row],[الكمية]] -> 3070
A38: 29 | B38: 29 | C38: Type-L8 Circular Spot 5W 3000K | D38: 20 | E38: عدد | F38: علبة بلاستيك | G38: 9 | H38: PVC | I38: 5 | J38: 3 | K38: =Table6[[#This Row],[سعر/م]]*Table6[[#This Row],[طول/وحدة (م)]] -> 15 | L38: سلك إنارة | M38: =Table6[[#This Row],[طول/وحدة (م)]]*1.1 -> 5.5 | N38: 9 | O38: =Table6[[#This Row],[سعر/م.ط]]*Table6[[#This Row],[طول/وحدة (م.ط]] -> 49.5 | P38: 80 | Q38: =Table6[[#This Row],[تثبيت وتوصيل]]+Table6[[#This Row],[إجمالي سلك/وحدة]]+Table6[[#This Row],[إجمالي ماسورة/وحدة]]+Table6[[#This Row],[سعر العلبة /وحدة]] -> 153.5 | R38: =Table6[[#This Row],[★الوحدة]]*Table6[[#This Row],[الكمية]] -> 3070
A39: 30 | B39: 30 | C39: Type-L11 LED Panel 600×600 28W IP44 5000K | D39: 140 | E39: عدد | F39: علبة بلاستيك | G39: 9 | H39: PVC | I39: 5 | J39: 3 | K39: =Table6[[#This Row],[سعر/م]]*Table6[[#This Row],[طول/وحدة (م)]] -> 15 | L39: سلك إنارة | M39: =Table6[[#This Row],[طول/وحدة (م)]]*1.1 -> 5.5 | N39: 9 | O39: =Table6[[#This Row],[سعر/م.ط]]*Table6[[#This Row],[طول/وحدة (م.ط]] -> 49.5 | P39: 80 | Q39: =Table6[[#This Row],[تثبيت وتوصيل]]+Table6[[#This Row],[إجمالي سلك/وحدة]]+Table6[[#This Row],[إجمالي ماسورة/وحدة]]+Table6[[#This Row],[سعر العلبة /وحدة]] -> 153.5 | R39: =Table6[[#This Row],[★الوحدة]]*Table6[[#This Row],[الكمية]] -> 21490
A40: 31 | B40: 31 | C40: Type-L14B LED Linear 26W 1450مم IP22 4000K | D40: 30 | E40: عدد | F40: علبة بلاستيك | G40: 9 | H40: PVC | I40: 5 | J40: 3 | K40: =Table6[[#This Row],[سعر/م]]*Table6[[#This Row],[طول/وحدة (م)]] -> 15 | L40: سلك إنارة | M40: =Table6[[#This Row],[طول/وحدة (م)]]*1.1 -> 5.5 | N40: 9 | O40: =Table6[[#This Row],[سعر/م.ط]]*Table6[[#This Row],[طول/وحدة (م.ط]] -> 49.5 | P40: 80 | Q40: =Table6[[#This Row],[تثبيت وتوصيل]]+Table6[[#This Row],[إجمالي سلك/وحدة]]+Table6[[#This Row],[إجمالي ماسورة/وحدة]]+Table6[[#This Row],[سعر العلبة /وحدة]] -> 153.5 | R40: =Table6[[#This Row],[★الوحدة]]*Table6[[#This Row],[الكمية]] -> 4605
A41: 32 | B41: 32 | C41: Type-L15 LED Surface 36W مع بطارية احتياطية 6000K | D41: 6 | E41: عدد | F41: علبة بلاستيك | G41: 9 | H41: PVC | I41: 5 | J41: 3 | K41: =Table6[[#This Row],[سعر/م]]*Table6[[#This Row],[طول/وحدة (م)]] -> 15 | L41: سلك إنارة | M41: =Table6[[#This Row],[طول/وحدة (م)]]*1.1 -> 5.5 | N41: 9 | O41: =Table6[[#This Row],[سعر/م.ط]]*Table6[[#This Row],[طول/وحدة (م.ط]] -> 49.5 | P41: 80 | Q41: =Table6[[#This Row],[تثبيت وتوصيل]]+Table6[[#This Row],[إجمالي سلك/وحدة]]+Table6[[#This Row],[إجمالي ماسورة/وحدة]]+Table6[[#This Row],[سعر العلبة /وحدة]] -> 153.5 | R41: =Table6[[#This Row],[★الوحدة]]*Table6[[#This Row],[الكمية]] -> 921
A42: 33 | B42: 33 | C42: Type-L18 LED Cove Light مخفية 3000K | D42: 111 | E42: م.ط | F42: علبة بلاستيك | G42: 9 | H42: PVC | I42: 5 | J42: 3 | K42: =Table6[[#This Row],[سعر/م]]*Table6[[#This Row],[طول/وحدة (م)]] -> 15 | L42: سلك إنارة | M42: =Table6[[#This Row],[طول/وحدة (م)]]*1.1 -> 5.5 | N42: 9 | O42: =Table6[[#This Row],[سعر/م.ط]]*Table6[[#This Row],[طول/وحدة (م.ط]] -> 49.5 | R42: =Table6[[#This Row],[★الوحدة]]*Table6[[#This Row],[الكمية]] -> 0
A43: 34 | B43: 34 | C43: LED Power Supply IP20 240V/24V للـ L18 | D43: 12 | E43: عدد | F43: علبة بلاستيك | G43: 9 | H43: PVC | I43: 5 | J43: 3 | K43: =Table6[[#This Row],[سعر/م]]*Table6[[#This Row],[طول/وحدة (م)]] -> 15 | L43: سلك إنارة | M43: =Table6[[#This Row],[طول/وحدة (م)]]*1.1 -> 5.5 | N43: 9 | O43: =Table6[[#This Row],[سعر/م.ط]]*Table6[[#This Row],[طول/وحدة (م.ط]] -> 49.5 | P43: 90 | Q43: =Table6[[#This Row],[تثبيت وتوصيل]]+Table6[[#This Row],[إجمالي سلك/وحدة]]+Table6[[#This Row],[إجمالي ماسورة/وحدة]]+Table6[[#This Row],[سعر العلبة /وحدة]] -> 163.5 | R43: =Table6[[#This Row],[★الوحدة]]*Table6[[#This Row],[الكمية]] -> 1962
A44: 35 | B44: 35 | C44: زر لمس KNX تحكم إنارة | D44: 4 | E44: عدد | F44: علبة بلاستيك | G44: 9 | H44: PVC | I44: 5 | J44: 3 | K44: =Table6[[#This Row],[سعر/م]]*Table6[[#This Row],[طول/وحدة (م)]] -> 15 | L44: سلك إنارة | M44: =Table6[[#This Row],[طول/وحدة (م)]]*1.1 -> 5.5 | N44: 9 | O44: =Table6[[#This Row],[سعر/م.ط]]*Table6[[#This Row],[طول/وحدة (م.ط]] -> 49.5 | P44: 80 | Q44: =Table6[[#This Row],[تثبيت وتوصيل]]+Table6[[#This Row],[إجمالي سلك/وحدة]]+Table6[[#This Row],[إجمالي ماسورة/وحدة]]+Table6[[#This Row],[سعر العلبة /وحدة]] -> 153.5 | R44: =Table6[[#This Row],[★الوحدة]]*Table6[[#This Row],[الكمية]] -> 614
...

Sheet بريك داون تيار خفيف
A1: م | B1: رقم البند | C1: وصف البند | D1: الكمية | E1: الوحدة | F1: نوع العلبة | G1: سعر العلبة /وحدة | H1: نوع الماسورة | I1: طول/وحدة (م) | J1: سعر/م | K1: إجمالي ماسورة/وحدة | L1: نوع السلك | M1: طول/وحدة (م)2 | N1: سعر/م.ط | O1: إجمالي سلك/وحدة | P1: تثبيت وتوصيل | Q1: ★الوحدة | R1: ★الإجمالي
A3: ◄ نظام الإذاعة PA والإخلاء
A4: 1 | B4: 1 | C4: Ceiling Speaker L-VCP06A/EN 6W EN54 | D4: 32 | E4: عدد | F4: EMT | G4: 15 | H4: EMT | I4: 6 | J4: 5 | K4: =Table7[[#This Row],[سعر/م]]*Table7[[#This Row],[سعر العلبة /وحدة]] -> 75 | L4: 2x2.5mm2 cables | M4: =1.1*Table7[[#This Row],[طول/وحدة (م)]] -> 6.6 | N4: 8 | O4: =Table7[[#This Row],[سعر/م.ط]]*Table7[[#This Row],[طول/وحدة (م)2]] -> 52.8 | Q4: =Table7[[#This Row],[تثبيت وتوصيل]]+Table7[[#This Row],[إجمالي سلك/وحدة]]+Table7[[#This Row],[إجمالي ماسورة/وحدة]]+Table7[[#This Row],[سعر العلبة /وحدة]] -> 142.8 | R4: =Table7[[#This Row],[★الوحدة]]*Table7[[#This Row],[الكمية]] -> 4569.6
A5: 2 | B5: 2 | C5: Wall Speaker L-VWM06A 6W Metal EN54 | D5: 4 | E5: عدد | F5: EMT | G5: 15 | H5: EMT | I5: 6 | J5: 5 | K5: =Table7[[#This Row],[سعر/م]]*Table7[[#This Row],[سعر العلبة /وحدة]] -> 75 | L5: 2x2.5mm2 cables | M5: =1.1*Table7[[#This Row],[طول/وحدة (م)]] -> 6.6 | N5: 8 | O5: =Table7[[#This Row],[سعر/م.ط]]*Table7[[#This Row],[طول/وحدة (م)2]] -> 52.8 | Q5: =Table7[[#This Row],[تثبيت وتوصيل]]+Table7[[#This Row],[إجمالي سلك/وحدة]]+Table7[[#This Row],[إجمالي ماسورة/وحدة]]+Table7[[#This Row],[سعر العلبة /وحدة]] -> 142.8 | R5: =Table7[[#This Row],[★الوحدة]]*Table7[[#This Row],[الكمية]] -> 571.2
A6: 3 | B6: 3 | C6: Horn Speaker L-PHP30A 30/15W | D6: 8 | E6: عدد | F6: EMT | G6: 15 | H6: EMT | I6: 6 | J6: 5 | K6: =Table7[[#This Row],[سعر/م]]*Table7[[#This Row],[سعر العلبة /وحدة]] -> 75 | L6: 2x2.5mm2 cables | M6: =1.1*Table7[[#This Row],[طول/وحدة (م)]] -> 6.6 | N6: 8 | O6: =Table7[[#This Row],[سعر/م.ط]]*Table7[[#This Row],[طول/وحدة (م)2]] -> 52.8 | Q6: =Table7[[#This Row],[تثبيت وتوصيل]]+Table7[[#This Row],[إجمالي سلك/وحدة]]+Table7[[#This Row],[إجمالي ماسورة/وحدة]]+Table7[[#This Row],[سعر العلبة /وحدة]] -> 142.8 | R6: =Table7[[#This Row],[★الوحدة]]*Table7[[#This Row],[الكمية]] -> 1142.4
A7: 4 | B7: 4 | C7: Volume Control Switch 60W أبيض | D7: 6 | E7: عدد | F7: EMT | G7: 15 | H7: EMT | I7: 6 | J7: 5 | K7: =Table7[[#This Row],[سعر/م]]*Table7[[#This Row],[سعر العلبة /وحدة]] -> 75 | L7: 2x2.5mm2 cables | M7: =1.1*Table7[[#This Row],[طول/وحدة (م)]] -> 6.6 | N7: 8 | O7: =Table7[[#This Row],[سعر/م.ط]]*Table7[[#This Row],[طول/وحدة (م)2]] -> 52.8 | Q7: =Table7[[#This Row],[تثبيت وتوصيل]]+Table7[[#This Row],[إجمالي سلك/وحدة]]+Table7[[#This Row],[إجمالي ماسورة/وحدة]]+Table7[[#This Row],[سعر العلبة /وحدة]] -> 142.8 | R7: =Table7[[#This Row],[★الوحدة]]*Table7[[#This Row],[الكمية]] -> 856.8
A9: ◄ نظام MATV
